Workbook

Sheet Instructions
A1: MAESTRO v1.0 — Test Case Register
A3: Project | B3: MAESTRO — Safe Multi-Agent System for NL-Driven Desktop Task Automation (Group 298, Amity)
A4: Source | B4: Project/tests/ — 15 modules. Parametrised tests appear once per case, so rows > function count.
A5: Automated run | B5: 27 Sep 2026 · macOS (M2 Pro), Python 3.12, pytest, venv Project/.venv
A7: HOW TO USE
A8: Yellow cells | B8: Are for you to fill in: Manual Result, Tested By, Test Date, Remarks (sheet 'Test Cases', columns K–N).
A9: Manual Result | B9: Pick from the dropdown: Pass / Fail / Blocked / Not Run. Cells turn green / red / amber.
A10: Automated Result | B10: Column H is what pytest reported on the run above. Do not edit it; record your own verdict in column K.
A11: Key claim | B11: 'Yes' marks the seven tests that pin the project's core safety claims — examiners are likely to ask about these.
A12: Summary sheet | B12: Updates automatically as you mark results (counts and % complete per area).
A13: Re-run the suite | B13: cd Project && .venv/bin/python -m pytest -q
A15: EXAMPLE OF A MARKED ROW
A16: Manual Result | B16: Pass
A17: Tested By | B17: Shashank Gupta
A18: Test Date | B18: 28-Sep-2026
A19: Remarks | B19: Re-ran on Windows 11 laptop; tampered row 3 in audit.db, verify() returned False as expected.
A21: STATUS MEANINGS
A22: Pass | B22: Behaviour matches the description in column F.
A23: Fail | B23: Behaviour differs — describe what you saw in Remarks.
A24: Blocked | B24: Could not run (missing dependency, wrong OS, no network). Say why in Remarks.
A25: Not Run | B25: Not attempted yet (also the meaning of an empty cell).

Sheet Summary
A1: MAESTRO v1.0 — Test Summary
A2: Automated run: 27 Sep 2026 · macOS (M2 Pro), Python 3.12, pytest, venv Project/.venv. Manual columns update as you mark 'Test Cases'.
A4: Area | B4: Total | C4: Auto Passed | D4: Auto Skipped | E4: Auto Failed | F4: Manual Pass | G4: Manual Fail | H4: Blocked | I4: Not Run / Blank | J4: % Marked | K4: Manual Pass Rate
A5: Safety layer | B5: =COUNTIF('Test Cases'!$D$2:$D$380,$A5) | C5: =COUNTIFS('Test Cases'!$D$2:$D$380,$A5,'Test Cases'!$H$2:$H$380,"Passed") | D5: =COUNTIFS('Test Cases'!$D$2:$D$380,$A5,'Test Cases'!$H$2:$H$380,"Skipped") | E5: =COUNTIFS('Test Cases'!$D$2:$D$380,$A5,'Test Cases'!$H$2:$H$380,"Failed") | F5: =COUNTIFS('Test Cases'!$D$2:$D$380,$A5,'Test Cases'!$K$2:$K$380,"Pass") | G5: =COUNTIFS('Test Cases'!$D$2:$D$380,$A5,'Test Cases'!$K$2:$K$380,"Fail") | H5: =COUNTIFS('Test Cases'!$D$2:$D$380,$A5,'Test Cases'!$K$2:$K$380,"Blocked") | I5: =B5-F5-G5-H5 | J5: =IF(B5=0,0,(F5+G5+H5)/B5) | K5: =IF((F5+G5)=0,"-",F5/(F5+G5))
A6: Executors | B6: =COUNTIF('Test Cases'!$D$2:$D$380,$A6) | C6: =COUNTIFS('Test Cases'!$D$2:$D$380,$A6,'Test Cases'!$H$2:$H$380,"Passed") | D6: =COUNTIFS('Test Cases'!$D$2:$D$380,$A6,'Test Cases'!$H$2:$H$380,"Skipped") | E6: =COUNTIFS('Test Cases'!$D$2:$D$380,$A6,'Test Cases'!$H$2:$H$380,"Failed") | F6: =COUNTIFS('Test Cases'!$D$2:$D$380,$A6,'Test Cases'!$K$2:$K$380,"Pass") | G6: =COUNTIFS('Test Cases'!$D$2:$D$380,$A6,'Test Cases'!$K$2:$K$380,"Fail") | H6: =COUNTIFS('Test Cases'!$D$2:$D$380,$A6,'Test Cases'!$K$2:$K$380,"Blocked") | I6: =B6-F6-G6-H6 | J6: =IF(B6=0,0,(F6+G6+H6)/B6) | K6: =IF((F6+G6)=0,"-",F6/(F6+G6))
A7: NLP (intent / entities) | B7: =COUNTIF('Test Cases'!$D$2:$D$380,$A7) | C7: =COUNTIFS('Test Cases'!$D$2:$D$380,$A7,'Test Cases'!$H$2:$H$380,"Passed") | D7: =COUNTIFS('Test Cases'!$D$2:$D$380,$A7,'Test Cases'!$H$2:$H$380,"Skipped") | E7: =COUNTIFS('Test Cases'!$D$2:$D$380,$A7,'Test Cases'!$H$2:$H$380,"Failed") | F7: =COUNTIFS('Test Cases'!$D$2:$D$380,$A7,'Test Cases'!$K$2:$K$380,"Pass") | G7: =COUNTIFS('Test Cases'!$D$2:$D$380,$A7,'Test Cases'!$K$2:$K$380,"Fail") | H7: =COUNTIFS('Test Cases'!$D$2:$D$380,$A7,'Test Cases'!$K$2:$K$380,"Blocked") | I7: =B7-F7-G7-H7 | J7: =IF(B7=0,0,(F7+G7+H7)/B7) | K7: =IF((F7+G7)=0,"-",F7/(F7+G7))
A8: Planner | B8: =COUNTIF('Test Cases'!$D$2:$D$380,$A8) | C8: =COUNTIFS('Test Cases'!$D$2:$D$380,$A8,'Test Cases'!$H$2:$H$380,"Passed") | D8: =COUNTIFS('Test Cases'!$D$2:$D$380,$A8,'Test Cases'!$H$2:$H$380,"Skipped") | E8: =COUNTIFS('Test Cases'!$D$2:$D$380,$A8,'Test Cases'!$H$2:$H$380,"Failed") | F8: =COUNTIFS('Test Cases'!$D$2:$D$380,$A8,'Test Cases'!$K$2:$K$380,"Pass") | G8: =COUNTIFS('Test Cases'!$D$2:$D$380,$A8,'Test Cases'!$K$2:$K$380,"Fail") | H8: =COUNTIFS('Test Cases'!$D$2:$D$380,$A8,'Test Cases'!$K$2:$K$380,"Blocked") | I8: =B8-F8-G8-H8 | J8: =IF(B8=0,0,(F8+G8+H8)/B8) | K8: =IF((F8+G8)=0,"-",F8/(F8+G8))
A9: Action IR | B9: =COUNTIF('Test Cases'!$D$2:$D$380,$A9) | C9: =COUNTIFS('Test Cases'!$D$2:$D$380,$A9,'Test Cases'!$H$2:$H$380,"Passed") | D9: =COUNTIFS('Test Cases'!$D$2:$D$380,$A9,'Test Cases'!$H$2:$H$380,"Skipped") | E9: =COUNTIFS('Test Cases'!$D$2:$D$380,$A9,'Test Cases'!$H$2:$H$380,"Failed") | F9: =COUNTIFS('Test Cases'!$D$2:$D$380,$A9,'Test Cases'!$K$2:$K$380,"Pass") | G9: =COUNTIFS('Test Cases'!$D$2:$D$380,$A9,'Test Cases'!$K$2:$K$380,"Fail") | H9: =COUNTIFS('Test Cases'!$D$2:$D$380,$A9,'Test Cases'!$K$2:$K$380,"Blocked") | I9: =B9-F9-G9-H9 | J9: =IF(B9=0,0,(F9+G9+H9)/B9) | K9: =IF((F9+G9)=0,"-",F9/(F9+G9))
A10: Dataset & evaluation | B10: =COUNTIF('Test Cases'!$D$2:$D$380,$A10) | C10: =COUNTIFS('Test Cases'!$D$2:$D$380,$A10,'Test Cases'!$H$2:$H$380,"Passed") | D10: =COUNTIFS('Test Cases'!$D$2:$D$380,$A10,'Test Cases'!$H$2:$H$380,"Skipped") | E10: =COUNTIFS('Test Cases'!$D$2:$D$380,$A10,'Test Cases'!$H$2:$H$380,"Failed") | F10: =COUNTIFS('Test Cases'!$D$2:$D$380,$A10,'Test Cases'!$K$2:$K$380,"Pass") | G10: =COUNTIFS('Test Cases'!$D$2:$D$380,$A10,'Test Cases'!$K$2:$K$380,"Fail") | H10: =COUNTIFS('Test Cases'!$D$2:$D$380,$A10,'Test Cases'!$K$2:$K$380,"Blocked") | I10: =B10-F10-G10-H10 | J10: =IF(B10=0,0,(F10+G10+H10)/B10) | K10: =IF((F10+G10)=0,"-",F10/(F10+G10))
A11: Orchestrator | B11: =COUNTIF('Test Cases'!$D$2:$D$380,$A11) | C11: =COUNTIFS('Test Cases'!$D$2:$D$380,$A11,'Test Cases'!$H$2:$H$380,"Passed") | D11: =COUNTIFS('Test Cases'!$D$2:$D$380,$A11,'Test Cases'!$H$2:$H$380,"Skipped") | E11: =COUNTIFS('Test Cases'!$D$2:$D$380,$A11,'Test Cases'!$H$2:$H$380,"Failed") | F11: =COUNTIFS('Test Cases'!$D$2:$D$380,$A11,'Test Cases'!$K$2:$K$380,"Pass") | G11: =COUNTIFS('Test Cases'!$D$2:$D$380,$A11,'Test Cases'!$K$2:$K$380,"Fail") | H11: =COUNTIFS('Test Cases'!$D$2:$D$380,$A11,'Test Cases'!$K$2:$K$380,"Blocked") | I11: =B11-F11-G11-H11 | J11: =IF(B11=0,0,(F11+G11+H11)/B11) | K11: =IF((F11+G11)=0,"-",F11/(F11+G11))
A12: Agents (Summarizer / Verifier) | B12: =COUNTIF('Test Cases'!$D$2:$D$380,$A12) | C12: =COUNTIFS('Test Cases'!$D$2:$D$380,$A12,'Test Cases'!$H$2:$H$380,"Passed") | D12: =COUNTIFS('Test Cases'!$D$2:$D$380,$A12,'Test Cases'!$H$2:$H$380,"Skipped") | E12: =COUNTIFS('Test Cases'!$D$2:$D$380,$A12,'Test Cases'!$H$2:$H$380,"Failed") | F12: =COUNTIFS('Test Cases'!$D$2:$D$380,$A12,'Test Cases'!$K$2:$K$380,"Pass") | G12: =COUNTIFS('Test Cases'!$D$2:$D$380,$A12,'Test Cases'!$K$2:$K$380,"Fail") | H12: =COUNTIFS('Test Cases'!$D$2:$D$380,$A12,'Test Cases'!$K$2:$K$380,"Blocked") | I12: =B12-F12-G12-H12 | J12: =IF(B12=0,0,(F12+G12+H12)/B12) | K12: =IF((F12+G12)=0,"-",F12/(F12+G12))
A13: Memory | B13: =COUNTIF('Test Cases'!$D$2:$D$380,$A13) | C13: =COUNTIFS('Test Cases'!$D$2:$D$380,$A13,'Test Cases'!$H$2:$H$380,"Passed") | D13: =COUNTIFS('Test Cases'!$D$2:$D$380,$A13,'Test Cases'!$H$2:$H$380,"Skipped") | E13: =COUNTIFS('Test Cases'!$D$2:$D$380,$A13,'Test Cases'!$H$2:$H$380,"Failed") | F13: =COUNTIFS('Test Cases'!$D$2:$D$380,$A13,'Test Cases'!$K$2:$K$380,"Pass") | G13: =COUNTIFS('Test Cases'!$D$2:$D$380,$A13,'Test Cases'!$K$2:$K$380,"Fail") | H13: =COUNTIFS('Test Cases'!$D$2:$D$380,$A13,'Test Cases'!$K$2:$K$380,"Blocked") | I13: =B13-F13-G13-H13 | J13: =IF(B13=0,0,(F13+G13+H13)/B13) | K13: =IF((F13+G13)=0,"-",F13/(F13+G13))
A14: Pipeline (end to end) | B14: =COUNTIF('Test Cases'!$D$2:$D$380,$A14) | C14: =COUNTIFS('Test Cases'!$D$2:$D$380,$A14,'Test Cases'!$H$2:$H$380,"Passed") | D14: =COUNTIFS('Test Cases'!$D$2:$D$380,$A14,'Test Cases'!$H$2:$H$380,"Skipped") | E14: =COUNTIFS('Test Cases'!$D$2:$D$380,$A14,'Test Cases'!$H$2:$H$380,"Failed") | F14: =COUNTIFS('Test Cases'!$D$2:$D$380,$A14,'Test Cases'!$K$2:$K$380,"Pass") | G14: =COUNTIFS('Test Cases'!$D$2:$D$380,$A14,'Test Cases'!$K$2:$K$380,"Fail") | H14: =COUNTIFS('Test Cases'!$D$2:$D$380,$A14,'Test Cases'!$K$2:$K$380,"Blocked") | I14: =B14-F14-G14-H14 | J14: =IF(B14=0,0,(F14+G14+H14)/B14) | K14: =IF((F14+G14)=0,"-",F14/(F14+G14))
A15: Conversation / clarification | B15: =COUNTIF('Test Cases'!$D$2:$D$380,$A15) | C15: =COUNTIFS('Test Cases'!$D$2:$D$380,$A15,'Test Cases'!$H$2:$H$380,"Passed") | D15: =COUNTIFS('Test Cases'!$D$2:$D$380,$A15,'Test Cases'!$H$2:$H$380,"Skipped") | E15: =COUNTIFS('Test Cases'!$D$2:$D$380,$A15,'Test Cases'!$H$2:$H$380,"Failed") | F15: =COUNTIFS('Test Cases'!$D$2:$D$380,$A15,'Test Cases'!$K$2:$K$380,"Pass") | G15: =COUNTIFS('Test Cases'!$D$2:$D$380,$A15,'Test Cases'!$K$2:$K$380,"Fail") | H15: =COUNTIFS('Test Cases'!$D$2:$D$380,$A15,'Test Cases'!$K$2:$K$380,"Blocked") | I15: =B15-F15-G15-H15 | J15: =IF(B15=0,0,(F15+G15+H15)/B15) | K15: =IF((F15+G15)=0,"-",F15/(F15+G15))
A16: Browser session | B16: =COUNTIF('Test Cases'!$D$2:$D$380,$A16) | C16: =COUNTIFS('Test Cases'!$D$2:$D$380,$A16,'Test Cases'!$H$2:$H$380,"Passed") | D16: =COUNTIFS('Test Cases'!$D$2:$D$380,$A16,'Test Cases'!$H$2:$H$380,"Skipped") | E16: =COUNTIFS('Test Cases'!$D$2:$D$380,$A16,'Test Cases'!$H$2:$H$380,"Failed") | F16: =COUNTIFS('Test Cases'!$D$2:$D$380,$A16,'Test Cases'!$K$2:$K$380,"Pass") | G16: =COUNTIFS('Test Cases'!$D$2:$D$380,$A16,'Test Cases'!$K$2:$K$380,"Fail") | H16: =COUNTIFS('Test Cases'!$D$2:$D$380,$A16,'Test Cases'!$K$2:$K$380,"Blocked") | I16: =B16-F16-G16-H16 | J16: =IF(B16=0,0,(F16+G16+H16)/B16) | K16: =IF((F16+G16)=0,"-",F16/(F16+G16))
... A19: Review fixes (regressions) | B19: =COUNTIF('Test Cases'!$D$2:$D$380,$A19) | C19: =COUNTIFS('Test Cases'!$D$2:$D$380,$A19,'Test Cases'!$H$2:$H$380,"Passed") | D19: =COUNTIFS('Test Cases'!$D$2:$D$380,$A19,'Test Cases'!$H$2:$H$380,"Skipped") | E19: =COUNTIFS('Test Cases'!$D$2:$D$380,$A19,'Test Cases'!$H$2:$H$380,"Failed") | F19: =COUNTIFS('Test Cases'!$D$2:$D$380,$A19,'Test Cases'!$K$2:$K$380,"Pass") | G19: =COUNTIFS('Test Cases'!$D$2:$D$380,$A19,'Test Cases'!$K$2:$K$380,"Fail") | H19: =COUNTIFS('Test Cases'!$D$2:$D$380,$A19,'Test Cases'!$K$2:$K$380,"Blocked") | I19: =B19-F19-G19-H19 | J19: =IF(B19=0,0,(F19+G19+H19)/B19) | K19: =IF((F19+G19)=0,"-",F19/(F19+G19))
A20: TOTAL | B20: =SUM(B5:B19) | C20: =SUM(C5:C19) | D20: =SUM(D5:D19) | E20: =SUM(E5:E19) | F20: =SUM(F5:F19) | G20: =SUM(G5:G19) | H20: =SUM(H5:H19) | I20: =SUM(I5:I19) | J20: =IF(B20=0,0,(F20+G20+H20)/B20) | K20: =IF((F20+G20)=0,"-",F20/(F20+G20))
A22: Notes
A23: Skipped = 9 browser-session tests; they need Playwright + Chromium (pip install -e ".[browser]" && playwright install chromium).
A24: Manual Pass Rate ignores Blocked and Not Run: Pass / (Pass + Fail).
A25: Key-claim tests are flagged in column G of 'Test Cases' — filter on 'Yes' to see them.

Sheet Test Cases
A1: S.No | B1: Test ID | C1: Module | D1: Area | E1: Test Function | F1: What It Verifies | G1: Key Claim | H1: Automated Result | I1: Time (s) | J1: Skip Reason | K1: Manual Result | L1: Tested By | M1: Test Date | N1: Remarks
A2: 1 | B2: TC-001 | C2: test_safety.py | D2: Safety layer | E2: test_allowlisted_path_is_allowed | F2: Allowlisted path is allowed. | H2: Passed | I2: 0.004
A3: 2 | B3: TC-002 | C3: test_safety.py | D3: Safety layer | E3: test_path_outside_allowlist_is_outside | F3: Path outside allowlist is outside. | H3: Passed | I3: 0.003
A4: 3 | B4: TC-003 | C4: test_safety.py | D4: Safety layer | E4: test_denylisted_directory_is_denied | F4: Denylisted directory is denied. | H4: Passed | I4: 0.003
A5: 4 | B5: TC-004 | C5: test_safety.py | D5: Safety layer | E5: test_traversal_does_not_escape_the_allowlist | F5: `workspace/../../.ssh/x` must be resolved BEFORE matching. | G5: Yes | H5: Passed | I5: 0.003
A6: 5 | B6: TC-005 | C6: test_safety.py | D6: Safety layer | E6: test_traversal_out_of_the_sandbox_is_not_allowed | F6: Traversal out of the sandbox is not allowed. | H6: Passed | I6: 0.003
A7: 6 | B7: TC-006 | C7: test_safety.py | D7: Safety layer | E7: test_symlink_into_a_denied_dir_is_denied | F7: A symlink inside an allowed directory pointing at a denied one is denied. | H7: Passed | I7: 0.004
A8: 7 | B8: TC-007 | C8: test_safety.py | D8: Safety layer | E8: test_denied_filename_pattern_anywhere | F8: Denied filename pattern anywhere. | H8: Passed | I8: 0.006
A9: 8 | B9: TC-008 | C9: test_safety.py | D9: Safety layer | E9: test_dot_ssh_as_any_component_is_denied | F9: Dot ssh as any component is denied. | H9: Passed | I9: 0.015
A10: 9 | B10: TC-009 | C10: test_safety.py | D10: Safety layer | E10: test_windows_system_paths_denied_on_every_platform | F10: One list, both platforms — so the cross-platform differential test in docs/02 §7 compares identical policy rather than two policies. | H10: Passed | I10: 0.007
A11: 10 | B11: TC-010 | C11: test_safety.py | D11: Safety layer | E11: test_unparseable_path_fails_closed | F11: Unparseable path fails closed. | H11: Passed | I11: 0.002
A12: 11 | B12: TC-011 | C12: test_safety.py | D12: Safety layer | E12: test_policy_explains_itself | F12: Policy explains itself. | H12: Passed | I12: 0.003
A13: 12 | B13: TC-012 | C13: test_safety.py | D13: Safety layer | E13: test_read_only_verb_in_workspace_is_r0 | F13: Read only verb in workspace is r0. | H13: Passed | I13: 0.003
A14: 13 | B14: TC-013 | C14: test_safety.py | D14: Safety layer | E14: test_move_is_r2_and_requires_consent | F14: Move is r2 and requires consent. | H14: Passed | I14: 0.003
A15: 14 | B15: TC-014 | C15: test_safety.py | D15: Safety layer | E15: test_unknown_verb_is_blocked_not_warned | F15: Unknown verb is blocked not warned. | H15: Passed | I15: 0.002
A16: 15 | B16: TC-015 | C16: test_safety.py | D16: Safety layer | E16: test_hard_blocked_verb_has_no_override | F16: Hard blocked verb has no override. | H16: Passed | I16: 0.003
A17: 16 | B17: TC-016 | C17: test_safety.py | D17: Safety layer | E17: test_denylisted_path_blocks_even_a_read | F17: Denylisted path blocks even a read. | H17: Passed | I17: 0.003
... A22: 21 | B22: TC-021 | C22: test_safety.py | D22: Safety layer | E22: test_scoring_is_deterministic | F22: NFR-07: the same plan yields the same verdict, every time. | H22: Passed | I22: 0.112
A23: 22 | B23: TC-022 | C23: test_safety.py | D23: Safety layer | E23: test_risk_hint_is_recorded_but_ignored | F23: A lying planner cannot downgrade risk. | G23: Yes | H23: Passed | I23: 0.003
A24: 23 | B24: TC-023 | C24: test_safety.py | D24: Safety layer | E24: test_a_lying_hint_cannot_unblock | F24: A lying hint cannot unblock. | H24: Passed | I24: 0.002
A25: 24 | B25: TC-024 | C25: test_safety.py | D25: Safety layer | E25: test_escalation_is_monotonic | F25: Every rule may only raise risk. An action that trips several rules ends at the maximum, never at the last one evaluated. | H25: Passed | I25: 0.003
A26: 25 | B26: TC-025 | C26: test_safety.py | D26: Safety layer | E26: test_plan_risk_is_the_max_over_actions | F26: Plan risk is the max over actions. | H26: Passed | I26: 0.003
A27: 26 | B27: TC-026 | C27: test_safety.py | D27: Safety layer | E27: test_gate_mapping | F27: Gate mapping. | H27: Passed | I27: 0.004
A28: 27 | B28: TC-027 | C28: test_safety.py | D28: Safety layer | E28: test_file_contents_are_untrusted | F28: File contents are untrusted. | H28: Passed | I28: 0.002
A29: 28 | B29: TC-028 | C29: test_safety.py | D29: Safety layer | E29: test_globbed_paths_are_derived_not_untrusted | F29: Globbed paths are derived not untrusted. | H29: Passed | I29: 0.002
A30: 29 | B30: TC-029 | C30: test_safety.py | D30: Safety layer | E30: test_untrusted_data_reaching_a_sensitive_arg_escalates | F30: Control #7 in docs/06 §6: laundering document text into a destination. | H30: Passed | I30: 0.004
A31: 30 | B31: TC-030 | C31: test_safety.py | D31: Safety layer | E31: test_taint_is_stamped_onto_the_plan | F31: Taint is stamped onto the plan. | H31: Passed | I31: 0.003
A32: 31 | B32: TC-031 | C32: test_safety.py | D32: Safety layer | E32: test_unknown_producer_verbs_are_assumed_untrusted | F32: Unknown producer verbs are assumed untrusted. | H32: Passed | I32: 0.001
A33: 32 | B33: TC-032 | C33: test_safety.py | D33: Safety layer | E33: test_static_budget_check_catches_scale | F33: Static budget check catches scale. | H33: Passed | I33: 0.001
A34: 33 | B34: TC-033 | C34: test_safety.py | D34: Safety layer | E34: test_dynamic_budget_raises | F34: Dynamic budget raises. | H34: Passed | I34: 0.001
A35: 34 | B35: TC-034 | C35: test_safety.py | D35: Safety layer | E35: test_file_budget_raises | F35: File budget raises. | H35: Passed | I35: 0.001
... A46: 45 | B46: TC-045 | C46: test_safety.py | D46: Safety layer | E46: test_audit_rejects_unknown_events | F46: Audit rejects unknown events. | H46: Passed | I46: 0.002
A47: 46 | B47: TC-046 | C47: test_safety.py | D47: Safety layer | E47: test_audit_tampering_is_detected | F47: Editing a historical row breaks verification of every row after it. | G47: Yes | H47: Passed | I47: 0.003
A48: 47 | B48: TC-047 | C48: test_safety.py | D48: Safety layer | E48: test_audit_deletion_is_detected | F48: Audit deletion is detected. | H48: Passed | I48: 0.004
A49: 48 | B49: TC-048 | C49: test_safety.py | D49: Safety layer | E49: test_audit_records_args_and_risk | F49: Audit records args and risk. | H49: Passed | I49: 0.003
A50: 49 | B50: TC-049 | C50: test_safety.py | D50: Safety layer | E50: test_hard_blocked_verbs_are_not_advertised_to_the_planner | F50: Hard blocked verbs are not advertised to the planner. | H50: Passed | I50: 0.001
A51: 50 | B51: TC-050 | C51: test_safety.py | D51: Safety layer | E51: test_every_registered_verb_has_an_executor_or_is_blocked | F51: Every registered verb has an executor or is blocked. | H51: Passed | I51: 0.001
A52: 51 | B52: TC-051 | C52: test_safety.py | D52: Safety layer | E52: test_unknown_verb_raises_registry_error | F52: Unknown verb raises registry error. | H52: Passed | I52: 0.001
A53: 52 | B53: TC-052 | C53: test_safety.py | D53: Safety layer | E53: test_validate_args_rejects_wrong_types | F53: Validate args rejects wrong types. | H53: Passed | I53: 0.001
A54: 53 | B54: TC-053 | C54: test_executors.py | D54: Executors | E54: test_resolve_substitutes_bound_variables | F54: Resolve substitutes bound variables. | H54: Passed | I54: 0.001
...
